Workbook

Sheet Read Me
B2: SPEQULA Chart of Accounts Mapping Workbook
B3: Corpus file 06a. Companion to 06_SPEQULA_MAPPING_SPEC.md.
B5: Purpose
B6: One worksheet per company. Every ledger in the source chart of accounts is assigned a canonical class, reviewed by a named person, and frozen as version 1. Nothing downstream computes until that freeze happens.
B8: The rule that makes this an afternoon rather than two weeks
B9: Sort by rupee value, not by count. A company with 900 ledgers will have around 40 that carry the great majority of the value. Map those, watch the coverage figure on the Coverage tab, and stop when it passes the threshold. The long tail sits in suspense.unmapped, visible and quantified, until someone cares.
B11: Workflow
B12: 1. Paste the source chart of accounts into the Mapping tab, columns A to F. Include the 12-month movement and the closing value, because the sort depends on them.
B13: 2. Sort descending by column G, absolute value carried.
B14: 3. Assign a canonical class in column H, choosing from the dropdown.
B15: 4. Record who approved it and when, columns L and M. Every row needs a name.
B16: 5. Check the Coverage tab. When mapped value passes the threshold, freeze as v1.
... B28: Many classes carry a decision id from corpus file 00. Where that decision is unresolved, the class still exists and can still be assigned; what is undefined is which statement line it lands on. Resolve the 22 P0-BLOCKING decisions before generating statements from this mapping.

Sheet Canonical Classes
A1: Canonical class taxonomy, version 0 (provisional)
A2: Shaded rows are judgement classes and are never assigned by an automated proposal. See the Read Me tab.
A4: Canonical class | B4: Stmt | C4: Statement line | D4: Profile | E4: Decision | F4: Notes
A5: revenue.product_sales | B5: P&L | C5: gross_revenue | D5: Both | F5: Domestic sale of goods
A6: revenue.service_income | B6: P&L | C6: gross_revenue | D6: Both
A7: revenue.job_work | B7: P&L | C7: gross_revenue | D7: Manufacturing | E7: D-010 | F7: Job work income received
A8: revenue.export_sales | B8: P&L | C8: gross_revenue | D8: Both | E8: D-008 | F8: Separate: currency and incentive treatment differ
A9: revenue.scrap_sales | B9: P&L | C9: gross_revenue | D9: Manufacturing | E9: D-009 | F9: May instead credit COGS
A10: revenue.other_operating | B10: P&L | C10: gross_revenue | D10: Both | F10: Freight and packing recovered
A11: revenue.commission_marketplace | B11: P&L | C11: gross_revenue | D11: Consumer | E11: D-004|D-061 | F11: Marketplace-earned commission, advertising and platform fee income -- OQ-006 resolution, 2026-08-24. GL-side counterpart to fact_channel_order_line.commission_earned/advertising_earned/platform_fee_earned; distinct from contra_revenue.commission_marketplace (commission a seller BEARS under the buyout model, D-004).
A12: contra_revenue.sales_returns | B12: P&L | C12: returns | D12: Both | E12: D-047
A13: contra_revenue.trade_discount | B13: P&L | C13: discounts | D13: Both | E13: D-003
A14: contra_revenue.cash_discount | B14: P&L | C14: discounts | D14: Both | E14: D-003
A15: contra_revenue.rate_difference | B15: P&L | C15: discounts | D15: Both | E15: D-003 | F15: Common in distribution
A16: contra_revenue.scheme_rebate | B16: P&L | C16: discounts | D16: Both | E16: D-003 | F16: May instead be opex
A17: contra_revenue.commission_marketplace | B17: P&L | C17: net_revenue | D17: Consumer | E17: D-004 | F17: Netted or shown as cost
A18: contra_revenue.shipping_recovered | B18: P&L | C18: net_revenue | D18: Consumer | E18: D-005
A19: cogs.raw_material | B19: P&L | C19: cogs | D19: Both
A20: cogs.packing_material | B20: P&L | C20: cogs | D20: Both | E20: D-013 | F20: Primary vs secondary may split
A21: cogs.stores_consumables | B21: P&L | C21: cogs | D21: Manufacturing
A22: opex.direct_labour | B22: P&L | C22: opex | D22: Manufacturing | E22: D-016 | F22: Needs a cost centre split that often does not exist. D-016 resolved 2026-08-24: opex, not COGS -- moved here from cogs.direct_labour.
A23: opex.power_fuel | B23: P&L | C23: opex | D23: Manufacturing | E23: D-015 | F23: D-015 resolved 2026-08-24: opex, not COGS -- moved here from cogs.power_fuel.
A24: cogs.job_work_charges | B24: P&L | C24: cogs | D24: Manufacturing | F24: Subcontracting paid out
A25: cogs.freight_inward | B25: P&L | C25: cogs | D25: Both | E25: D-012 | F25: Capitalised into inventory or expensed
A26: cogs.freight_outward | B26: P&L | C26: cogs | D26: Both | E26: D-011 | F26: The most contested line in the taxonomy
A27: cogs.fulfilment | B27: P&L | C27: cogs | D27: Consumer | E27: D-020 | F27: Warehousing and pick-pack
A28: cogs.payment_fees | B28: P&L | C28: cogs | D28: Consumer | E28: D-014 | F28: Gateway and COD
A29: cogs.stock_adjustment | B29: P&L | C29: cogs | D29: Both | E29: D-019 | F29: Physical vs book, write-downs
A30: cogs.absorption_variance | B30: P&L | C30: cogs | D30: Manufacturing | E30: D-017 | F30: JUDGEMENT CLASS
A31: opex.employee_cost | B31: P&L | C31: opex | D31: Both
A32: opex.rent | B32: P&L | C32: opex | D32: Both | E32: D-026
A33: opex.repairs_maintenance | B33: P&L | C33: opex | D33: Both
A34: opex.travel | B34: P&L | C34: opex | D34: Both
A35: opex.professional_fees | B35: P&L | C35: opex | D35: Both
A36: opex.marketing_advertising | B36: P&L | C36: opex | D36: Both | E36: D-023 | F36: Variable or fixed for consumer
A37: opex.selling_distribution | B37: P&L | C37: opex | D37: Both
A38: opex.store_rent | B38: P&L | C38: opex | D38: Consumer | E38: D-060 | F38: Retail store rent, CAM and HVAC -- offline manpower/rent per D-060 sits in the CM1 operating-cost rung, not COGS or marketing. Added 2026-08-24 for the apparel forecasting build (corpus/13).
A39: opex.store_personnel | B39: P&L | C39: opex | D39: Consumer | E39: D-060 | F39: Retail store-level personnel cost (store staff), distinct from opex.employee_cost (head office). D-060: offline manpower sits in the CM1 operating-cost rung. Added 2026-08-24, corpus/13.
A40: opex.franchise_commission | B40: P&L | C40: opex | D40: Consumer | E40: D-060 | F40: Commission paid to franchise partners operating COFO/FOFO stores -- a store-level operating cost, not COGS (it is not paid to a supplier of goods) and not marketing. Treated the same as offline manpower/rent per D-060's CM1 operating-cost rung. Added 2026-08-24, corpus/13.
A41: opex.admin_general | B41: P&L | C41: opex | D41: Both
...

Sheet Mapping
A1: Account mapping worksheet
A2: Paste the source chart of accounts into columns A to F. Sort descending by column G. Assign column H from the dropdown. Blue italic row 6 is a synthetic example: delete it.
A3: Company: ________________ Mapping version: 1 Effective from: ____________ Approved by: ________________
A5: Source code | B5: Source account name (verbatim) | C5: Parent group | D5: Type | E5: 12m movement (INR) | F5: Closing balance (INR) | G5: Value carried (INR) | H5: Canonical class | I5: Derived channel | J5: Derived geo | K5: Proposal reason | L5: Approved by | M5: Approved on | N5: Reviewer note
A6: 4001 | B6: Sales - Retail (Delhi) | C6: Sales Accounts | D6: Income | E6: 341200000 | F6: -52350000 | G6: =MAX(ABS(E6),ABS(F6)) | H6: revenue.product_sales | I6: retail | J6: north | K6: Sits under Sales Accounts, credit balance, movement consistent with a revenue stream | L6: B Singhal | M6: 2026-08-20 | N6: Channel and geo read from the ledger name
G7: =IF(AND(E7="",F7=""),"",MAX(ABS(E7),ABS(F7)))
G8: =IF(AND(E8="",F8=""),"",MAX(ABS(E8),ABS(F8)))
G9: =IF(AND(E9="",F9=""),"",MAX(ABS(E9),ABS(F9)))
G10: =IF(AND(E10="",F10=""),"",MAX(ABS(E10),ABS(F10)))
G11: =IF(AND(E11="",F11=""),"",MAX(ABS(E11),ABS(F11)))
G12: =IF(AND(E12="",F12=""),"",MAX(ABS(E12),ABS(F12)))
G13: =IF(AND(E13="",F13=""),"",MAX(ABS(E13),ABS(F13)))
G14: =IF(AND(E14="",F14=""),"",MAX(ABS(E14),ABS(F14)))
G15: =IF(AND(E15="",F15=""),"",MAX(ABS(E15),ABS(F15)))
G16: =IF(AND(E16="",F16=""),"",MAX(ABS(E16),ABS(F16)))
G17: =IF(AND(E17="",F17=""),"",MAX(ABS(E17),ABS(F17)))
G18: =IF(AND(E18="",F18=""),"",MAX(ABS(E18),ABS(F18)))
... G905: =IF(AND(E905="",F905=""),"",MAX(ABS(E905),ABS(F905)))

Sheet Coverage
A1: Coverage and freeze gate
A2: Every figure below recalculates from the Mapping tab. The number that matters is unmapped value in rupees, not the count of unmapped ledgers.
A5: Total ledgers in the chart | C5: =COUNTA(Mapping!B6:B905)
A6: Ledgers assigned a class | C6: =COUNTIF(Mapping!H6:H905,"<>")
A7: Ledgers in suspense | C7: =COUNTIF(Mapping!H6:H905,"suspense.unmapped") | D7: Acceptable, provided the value below is small
A8: Ledgers with no class at all | C8: =C5-C6 | D8: Must reach zero before freeze
A10: Total value carried | C10: =SUM(Mapping!G6:G905)
A11: Value mapped to a real class | C11: =SUMIFS(Mapping!G6:G905,Mapping!H6:H905,"<>",Mapping!H6:H905,"<>suspense.unmapped")
A12: Value in suspense | C12: =SUMIFS(Mapping!G6:G905,Mapping!H6:H905,"suspense.unmapped")
A13: Value with no class at all | C13: =C10-C11-C12 | D13: The figure to watch while reviewing
A15: Coverage, mapped value over total | C15: =IFERROR(C11/C10,0) | D15: Target 98% or higher. Threshold governed by DECISION-REQUIRED[D-053]
A16: Unmapped value, suspense plus unassigned | C16: =C12+C13 | D16: Display this on the data health screen at all times
A18: Rows approved by a named person | C18: =COUNTIF(Mapping!L6:L905,"<>")
A19: Rows assigned but not approved | C19: =C6-C18 | D19: Must reach zero before freeze
A21: FREEZE GATE | C21: =IF(AND(C8=0,C19=0,C15>=0.98),"PASS","BLOCKED") | D21: All three conditions: no unassigned ledgers, no unapproved rows, coverage at or above 98%
A23: A BLOCKED gate is not advisory. Metrics do not unlock and no statement is generated until it reads PASS. A half-mapped company producing partial statements is worse than one producing none.

Sheet Item Mapping
A1: Item Mapping
A2: One declared unit of measure per product family. A second unit arriving for the same family blocks every per-unit metric rather than being converted. See DECISION-REQUIRED[D-041].
A4: Source item code | B4: Source item name (verbatim) | C4: Canonical product category | D4: Product family | E4: Declared UOM | F4: Stock type | G4: Approved by | H4: Approved on
A5: RM-1001 | B5: HR Coil 3mm | C5: steel_flat | D5: hr_coil | E5: MT | F5: Raw material | G5: B Singhal | H5: 2026-08-20

Sheet Channel Mapping
A1: Channel Mapping
A2: Consumer profile only. The same marketplace commonly appears under three spellings across three years of order files. Target taxonomy governed by DECISION-REQUIRED[D-046].
A4: Source channel string (verbatim) | B4: Canonical channel | C4: Channel group | D4: Owned or third party | E4: Approved by | F4: Approved on
A5: AMZN-IN-SELLER-01 | B5: marketplace_amazon | C5: marketplace | D5: Third party | E5: B Singhal | F5: 2026-08-20
